Workbook

Sheet Transaksi
A1: Tanggal | B1: Barang | C1: Size | D1: Kode | E1: Jml | F1: Harga_Jual | G1: Pemasukan | H1: Modal | I1: Laba | J1: Total_Modal | K1: Total_Omzet | L1: Total_Laba
A2: 46110 | B2: Dewasa | C2: XL | D2: b04 | E2: 1 | F2: 37000 | G2: =E2*F2 -> 37000 | H2: =IFERROR(E2*_xlfn.XLOOKUP(D2,Stok_Baju!B:B,Stok_Baju!D:D),0) -> 20833.333 | I2: =G2-H2 -> 16166.667 | J2: =SUM(H:H) -> 7367500 | K2: =SUM(G:G) -> 14602000 | L2: =K2-J2 -> 7234500
A3: 46110 | B3: Setelan | C3: S | D3: a01 | E3: 1 | F3: 40000 | G3: =E3*F3 -> 40000 | H3: =IFERROR(E3*_xlfn.XLOOKUP(D3,Stok_Baju!B:B,Stok_Baju!D:D),0) -> 21666.667 | I3: =G3-H3 -> 18333.333
A4: 46110 | B4: Spandex | C4: M | D4: c01 | E4: 1 | F4: 50000 | G4: =E4*F4 -> 50000 | H4: =IFERROR(E4*_xlfn.XLOOKUP(D4,Stok_Baju!B:B,Stok_Baju!D:D),0) -> 31250 | I4: =G4-H4 -> 18750
A5: 46112 | B5: Dewasa | C5: L | D5: c03 | E5: 2 | F5: 45000 | G5: =E5*F5 -> 90000 | H5: =IFERROR(E5*_xlfn.XLOOKUP(D5,Stok_Baju!B:B,Stok_Baju!D:D),0) -> 70833.333 | I5: =G5-H5 -> 19166.667
A6: 46112 | B6: Setelan | C6: M | D6: a02 | E6: 1 | F6: 50000 | G6: =E6*F6 -> 50000 | H6: =IFERROR(E6*_xlfn.XLOOKUP(D6,Stok_Baju!B:B,Stok_Baju!D:D),0) -> 22916.667 | I6: =G6-H6 -> 27083.333
A7: 46112 | B7: Setelan | C7: S | D7: a01 | E7: 2 | F7: 50000 | G7: =E7*F7 -> 100000 | H7: =IFERROR(E7*_xlfn.XLOOKUP(D7,Stok_Baju!B:B,Stok_Baju!D:D),0) -> 43333.333 | I7: =G7-H7 -> 56666.667
A8: 46112 | B8: Setelan | C8: L | D8: a03 | E8: 4 | F8: 50000 | G8: =E8*F8 -> 200000 | H8: =IFERROR(E8*_xlfn.XLOOKUP(D8,Stok_Baju!B:B,Stok_Baju!D:D),0) -> 95000 | I8: =G8-H8 -> 105000
A9: 46112 | B9: Xseven | D9: x7 | E9: 4 | F9: 60000 | G9: =E9*F9 -> 240000 | H9: =IFERROR(E9*_xlfn.XLOOKUP(D9,Stok_Baju!B:B,Stok_Baju!D:D),0) -> 140000 | I9: =G9-H9 -> 100000
A10: 46114 | B10: Setelan | C10: S | D10: a01 | E10: 2 | F10: 45000 | G10: =IF(OR(E10="",F10=""),"",E10*F10) -> 90000 | H10: =IFERROR(E10*_xlfn.XLOOKUP(D10,Stok_Baju!B:B,Stok_Baju!D:D),0) -> 43333.333 | I10: =IF(G10="","",G10-H10) -> 46666.667
A11: 46114 | B11: Setelan | C11: M | D11: a02 | E11: 4 | F11: 45000 | G11: =IF(OR(E11="",F11=""),"",E11*F11) -> 180000 | H11: =IFERROR(E11*_xlfn.XLOOKUP(D11,Stok_Baju!B:B,Stok_Baju!D:D),0) -> 91666.667 | I11: =IF(G11="","",G11-H11) -> 88333.333
A12: 46114 | B12: Setelan | C12: L | D12: a03 | E12: 9 | F12: 45000 | G12: =IF(OR(E12="",F12=""),"",E12*F12) -> 405000 | H12: =IFERROR(E12*_xlfn.XLOOKUP(D12,Stok_Baju!B:B,Stok_Baju!D:D),0) -> 213750 | I12: =IF(G12="","",G12-H12) -> 191250
A13: 46114 | B13: Setelan | C13: XL | D13: a04 | E13: 3 | F13: 50000 | G13: =IF(OR(E13="",F13=""),"",E13*F13) -> 150000 | H13: =IFERROR(E13*_xlfn.XLOOKUP(D13,Stok_Baju!B:B,Stok_Baju!D:D),0) -> 76250 | I13: =IF(G13="","",G13-H13) -> 73750
A14: 46114 | B14: Dewasa | C14: S | D14: b01 | E14: 1 | F14: 45000 | G14: =IF(OR(E14="",F14=""),"",E14*F14) -> 45000 | H14: =IFERROR(E14*_xlfn.XLOOKUP(D14,Stok_Baju!B:B,Stok_Baju!D:D),0) -> 17083.333 | I14: =IF(G14="","",G14-H14) -> 27916.667
A15: 46114 | B15: Dewasa | C15: M | D15: b02 | E15: 3 | F15: 45000 | G15: =IF(OR(E15="",F15=""),"",E15*F15) -> 135000 | H15: =IFERROR(E15*_xlfn.XLOOKUP(D15,Stok_Baju!B:B,Stok_Baju!D:D),0) -> 55000 | I15: =IF(G15="","",G15-H15) -> 80000
A16: 46114 | B16: Dewasa | C16: L | D16: b03 | E16: 1 | F16: 45000 | G16: =IF(OR(E16="",F16=""),"",E16*F16) -> 45000 | H16: =IFERROR(E16*_xlfn.XLOOKUP(D16,Stok_Baju!B:B,Stok_Baju!D:D),0) -> 19583.333 | I16: =IF(G16="","",G16-H16) -> 25416.667
A17: 46114 | B17: Spandex | C17: M | D17: c01 | E17: 2 | F17: 50000 | G17: =IF(OR(E17="",F17=""),"",E17*F17) -> 100000 | H17: =IFERROR(E17*_xlfn.XLOOKUP(D17,Stok_Baju!B:B,Stok_Baju!D:D),0) -> 62500 | I17: =IF(G17="","",G17-H17) -> 37500
A18: 46114 | B18: Spandex | C18: L | D18: c02 | E18: 2 | F18: 50000 | G18: =IF(OR(E18="",F18=""),"",E18*F18) -> 100000 | H18: =IFERROR(E18*_xlfn.XLOOKUP(D18,Stok_Baju!B:B,Stok_Baju!D:D),0) -> 65833.333 | I18: =IF(G18="","",G18-H18) -> 34166.667
A19: 46114 | B19: Spandex | C19: XL | D19: c03 | E19: 5 | F19: 50000 | G19: =IF(OR(E19="",F19=""),"",E19*F19) -> 250000 | H19: =IFERROR(E19*_xlfn.XLOOKUP(D19,Stok_Baju!B:B,Stok_Baju!D:D),0) -> 177083.33 | I19: =IF(G19="","",G19-H19) -> 72916.667
A20: 46114 | B20: Spandex | C20: XXL | D20: c04 | E20: 1 | F20: 50000 | G20: =IF(OR(E20="",F20=""),"",E20*F20) -> 50000 | H20: =IFERROR(E20*_xlfn.XLOOKUP(D20,Stok_Baju!B:B,Stok_Baju!D:D),0) -> 40000 | I20: =IF(G20="","",G20-H20) -> 10000
A21: 46114 | B21: Xseven | C21: - | D21: x7 | E21: 1 | F21: 50000 | G21: =IF(OR(E21="",F21=""),"",E21*F21) -> 50000 | H21: =IFERROR(E21*_xlfn.XLOOKUP(D21,Stok_Baju!B:B,Stok_Baju!D:D),0) -> 35000 | I21: =IF(G21="","",G21-H21) -> 15000
... A36: 46127 | B36: Dewasa | C36: S | D36: b01 | E36: 1 | F36: 45000 | G36: =IF(OR(E36="",F36=""),"",E36*F36) -> 45000 | H36: =IFERROR(E36*_xlfn.XLOOKUP(D36,Stok_Baju!B:B,Stok_Baju!D:D),0) -> 17083.333 | I36: =IF(G36="","",G36-H36) -> 27916.667
A37: 46127 | B37: Xseven | D37: x7 | E37: 2 | F37: 60000 | G37: =IF(OR(E37="",F37=""),"",E37*F37) -> 120000 | H37: =IFERROR(E37*_xlfn.XLOOKUP(D37,Stok_Baju!B:B,Stok_Baju!D:D),0) -> 70000 | I37: =IF(G37="","",G37-H37) -> 50000
A38: 46127 | B38: Spandex | C38: XXL | D38: c04 | E38: 1 | F38: 60000 | G38: =IF(OR(E38="",F38=""),"",E38*F38) -> 60000 | H38: =IFERROR(E38*_xlfn.XLOOKUP(D38,Stok_Baju!B:B,Stok_Baju!D:D),0) -> 40000 | I38: =IF(G38="","",G38-H38) -> 20000
A39: 46128 | B39: Setelan | C39: S | D39: a01 | E39: 1 | F39: 0 | G39: =IF(OR(E39="",F39=""),"",E39*F39) -> 0 | H39: =IFERROR(E39*_xlfn.XLOOKUP(D39,Stok_Baju!B:B,Stok_Baju!D:D),0) -> 21666.667 | I39: =IF(G39="","",G39-H39) -> -21666.667
A40: 46128 | B40: Setelan | C40: S | D40: a01 | E40: 1 | F40: 50000 | G40: =IF(OR(E40="",F40=""),"",E40*F40) -> 50000 | H40: =IFERROR(E40*_xlfn.XLOOKUP(D40,Stok_Baju!B:B,Stok_Baju!D:D),0) -> 21666.667 | I40: =IF(G40="","",G40-H40) -> 28333.333
A41: 46128 | B41: Setelan | C41: M | D41: a02 | E41: 4 | F41: 50000 | G41: =IF(OR(E41="",F41=""),"",E41*F41) -> 200000 | H41: =IFERROR(E41*_xlfn.XLOOKUP(D41,Stok_Baju!B:B,Stok_Baju!D:D),0) -> 91666.667 | I41: =IF(G41="","",G41-H41) -> 108333.33
A42: 46128 | B42: Setelan | C42: L | D42: a03 | E42: 7 | F42: 50000 | G42: =IF(OR(E42="",F42=""),"",E42*F42) -> 350000 | H42: =IFERROR(E42*_xlfn.XLOOKUP(D42,Stok_Baju!B:B,Stok_Baju!D:D),0) -> 166250 | I42: =IF(G42="","",G42-H42) -> 183750
A43: 46128 | B43: Setelan | C43: XL | D43: a04 | E43: 6 | F43: 50000 | G43: =IF(OR(E43="",F43=""),"",E43*F43) -> 300000 | H43: =IFERROR(E43*_xlfn.XLOOKUP(D43,Stok_Baju!B:B,Stok_Baju!D:D),0) -> 152500 | I43: =IF(G43="","",G43-H43) -> 147500
A44: 46128 | B44: Dewasa | C44: S | D44: b01 | E44: 5 | F44: 45000 | G44: =IF(OR(E44="",F44=""),"",E44*F44) -> 225000 | H44: =IFERROR(E44*_xlfn.XLOOKUP(D44,Stok_Baju!B:B,Stok_Baju!D:D),0) -> 85416.667 | I44: =IF(G44="","",G44-H44) -> 139583.33
A45: 46128 | B45: Dewasa | C45: M | D45: b02 | E45: 9 | F45: 45000 | G45: =IF(OR(E45="",F45=""),"",E45*F45) -> 405000 | H45: =IFERROR(E45*_xlfn.XLOOKUP(D45,Stok_Baju!B:B,Stok_Baju!D:D),0) -> 165000 | I45: =IF(G45="","",G45-H45) -> 240000
A46: 46128 | B46: Dewasa | C46: L | D46: b03 | E46: 7 | F46: 45000 | G46: =IF(OR(E46="",F46=""),"",E46*F46) -> 315000 | H46: =IFERROR(E46*_xlfn.XLOOKUP(D46,Stok_Baju!B:B,Stok_Baju!D:D),0) -> 137083.33 | I46: =IF(G46="","",G46-H46) -> 177916.67
A47: 46128 | B47: Dewasa | C47: XL | D47: b04 | E47: 2 | F47: 45000 | G47: =IF(OR(E47="",F47=""),"",E47*F47) -> 90000 | H47: =IFERROR(E47*_xlfn.XLOOKUP(D47,Stok_Baju!B:B,Stok_Baju!D:D),0) -> 41666.667 | I47: =IF(G47="","",G47-H47) -> 48333.333
A48: 46128 | B48: Dewasa | C48: XXL | D48: b05 | E48: 1 | F48: 50000 | G48: =IF(OR(E48="",F48=""),"",E48*F48) -> 50000 | H48: =IFERROR(E48*_xlfn.XLOOKUP(D48,Stok_Baju!B:B,Stok_Baju!D:D),0) -> 24166.667 | I48: =IF(G48="","",G48-H48) -> 25833.333
A49: 46128 | B49: Spandex | C49: L | D49: c02 | E49: 2 | F49: 50000 | G49: =IF(OR(E49="",F49=""),"",E49*F49) -> 100000 | H49: =IFERROR(E49*_xlfn.XLOOKUP(D49,Stok_Baju!B:B,Stok_Baju!D:D),0) -> 65833.333 | I49: =IF(G49="","",G49-H49) -> 34166.667
... A52: 46128 | B52: Spandex | C52: XXL | D52: c04 | E52: 2 | F52: 60000 | G52: =IF(OR(E52="",F52=""),"",E52*F52) -> 120000 | H52: =IFERROR(E52*_xlfn.XLOOKUP(D52,Stok_Baju!B:B,Stok_Baju!D:D),0) -> 80000 | I52: =IF(G52="","",G52-H52) -> 40000
A53: 46128 | B53: Daster | D53: das | E53: 2 | F53: 45000 | G53: =IF(OR(E53="",F53=""),"",E53*F53) -> 90000 | H53: =IFERROR(E53*_xlfn.XLOOKUP(D53,Stok_Baju!B:B,Stok_Baju!D:D),0) -> 65000 | I53: =IF(G53="","",G53-H53) -> 25000
A54: 46128 | B54: Xseven | D54: x7 | E54: 5 | F54: 60000 | G54: =IF(OR(E54="",F54=""),"",E54*F54) -> 300000 | H54: =IFERROR(E54*_xlfn.XLOOKUP(D54,Stok_Baju!B:B,Stok_Baju!D:D),0) -> 175000 | I54: =IF(G54="","",G54-H54) -> 125000
A55: 46129 | B55: Setelan | C55: S | D55: a01 | E55: 1 | F55: 50000 | G55: =IF(OR(E55="",F55=""),"",E55*F55) -> 50000 | H55: =IFERROR(E55*_xlfn.XLOOKUP(D55,Stok_Baju!B:B,Stok_Baju!D:D),0) -> 21666.667 | I55: =IF(G55="","",G55-H55) -> 28333.333
A56: 46130 | B56: Setelan | C56: S | D56: a01 | E56: 1 | F56: 45000 | G56: =IF(OR(E56="",F56=""),"",E56*F56) -> 45000 | H56: =IFERROR(E56*_xlfn.XLOOKUP(D56,Stok_Baju!B:B,Stok_Baju!D:D),0) -> 21666.667 | I56: =IF(G56="","",G56-H56) -> 23333.333
...

Sheet Stok_Baju
A1: Barang_Size | B1: Kode | C1: Modal_lusinan | D1: Modal_Satuan | E1: Belanja | F1: Stok_Awal | G1: Lemari | H1: Pajangan_awal | I1: kePajangan | J1: Pajangan | K1: Brg_Keluar | L1: Total_stok | M1: Bulan | N1: Modal_bulan | O1: Total_Omzet | P1: Total_Laba
A2: Setelan S | B2: a01 | C2: =belanja!H3 -> 260000 | D2: =C2/12 -> 21666.667 | E2: =belanja!E3*12 -> 24 | F2: 34 | G2: =Table3[[#This Row],[Column10]]-Table3[[#This Row],[Column19]] -> 7 | H2: 46 | I2: =6+12 -> 18 | J2: =Table3[[#This Row],[Column6]]+Table3[[#This Row],[Column5]]-Table3[[#This Row],[Column13]] -> 27 | K2: =IF($B2="","",SUMIF(Transaksi!$D:$D,$B2,Transaksi!$E:$E)+IF($B2="das",SUMIFS(Transaksi!$E:$E,Transaksi!$B:$B,"Daster",Transaksi!$D:$D,""),0)+IF($B2="x7",SUMIFS(Transaksi!$E:$E,Transaksi!$B:$B,"Xseven",Transaksi!$D:$D,""),0)) -> 37 | L2: =Table3[[#This Row],[Column11]]+Table3[[#This Row],[Column19]] -> 34 | M2: April | N2: =SUMIFS(Transaksi!H:H,Transaksi!$A:$A,">="&DATE(2026,4,1),Transaksi!$A:$A,"<"&DATE(2026,5,1)) -> 5353750 | O2: =SUMIFS(Transaksi!G:G,Transaksi!$A:$A,">="&DATE(2026,4,1),Transaksi!$A:$A,"<"&DATE(2026,5,1)) -> 10580000 | P2: =SUMIFS(Transaksi!I:I,Transaksi!$A:$A,">="&DATE(2026,4,1),Transaksi!$A:$A,"<"&DATE(2026,5,1)) -> 5226250
A3: Setelan M | B3: a02 | C3: =belanja!H4 -> 275000 | D3: =C3/12 -> 22916.667 | E3: =belanja!E4*12 -> 24 | F3: 37 | G3: =Table3[[#This Row],[Column10]]-Table3[[#This Row],[Column19]] -> 10 | H3: 49 | I3: =12+2+2 -> 16 | J3: =Table3[[#This Row],[Column6]]+Table3[[#This Row],[Column5]]-Table3[[#This Row],[Column13]] -> 27 | K3: =IF($B3="","",SUMIF(Transaksi!$D:$D,$B3,Transaksi!$E:$E)+IF($B3="das",SUMIFS(Transaksi!$E:$E,Transaksi!$B:$B,"Daster",Transaksi!$D:$D,""),0)+IF($B3="x7",SUMIFS(Transaksi!$E:$E,Transaksi!$B:$B,"Xseven",Transaksi!$D:$D,""),0)) -> 38 | L3: =Table3[[#This Row],[Column11]]+Table3[[#This Row],[Column19]] -> 37 | M3: Mei | N3: =SUMIFS(Transaksi!H:H,Transaksi!$A:$A,">="&DATE(2026,5,1),Transaksi!$A:$A,"<"&DATE(2026,6,1)) -> 1567916.7 | O3: =SUMIFS(Transaksi!G:G,Transaksi!$A:$A,">="&DATE(2026,5,1),Transaksi!$A:$A,"<"&DATE(2026,6,1)) -> 3215000 | P3: =SUMIFS(Transaksi!I:I,Transaksi!$A:$A,">="&DATE(2026,5,1),Transaksi!$A:$A,"<"&DATE(2026,6,1)) -> 1647083.3
A4: Setelan L | B4: a03 | C4: =belanja!H5 -> 285000 | D4: =C4/12 -> 23750 | E4: =belanja!E5*12 -> 24 | F4: 40 | G4: =Table3[[#This Row],[Column10]]-Table3[[#This Row],[Column19]] -> 13 | H4: 62 | I4: =9+6 -> 15 | J4: =Table3[[#This Row],[Column6]]+Table3[[#This Row],[Column5]]-Table3[[#This Row],[Column13]] -> 27 | K4: =IF($B4="","",SUMIF(Transaksi!$D:$D,$B4,Transaksi!$E:$E)+IF($B4="das",SUMIFS(Transaksi!$E:$E,Transaksi!$B:$B,"Daster",Transaksi!$D:$D,""),0)+IF($B4="x7",SUMIFS(Transaksi!$E:$E,Transaksi!$B:$B,"Xseven",Transaksi!$D:$D,""),0)) -> 50 | L4: =Table3[[#This Row],[Column11]]+Table3[[#This Row],[Column19]] -> 40
A5: Setelan XL | B5: a04 | C5: =belanja!H6 -> 305000 | D5: =C5/12 -> 25416.667 | E5: =belanja!E6*12 -> 24 | F5: 26 | G5: =Table3[[#This Row],[Column10]]-Table3[[#This Row],[Column19]] -> 0 | H5: =34+24 -> 58 | I5: =6+6 -> 12 | J5: =Table3[[#This Row],[Column6]]+Table3[[#This Row],[Column5]]-Table3[[#This Row],[Column13]] -> 26 | K5: =IF($B5="","",SUMIF(Transaksi!$D:$D,$B5,Transaksi!$E:$E)+IF($B5="das",SUMIFS(Transaksi!$E:$E,Transaksi!$B:$B,"Daster",Transaksi!$D:$D,""),0)+IF($B5="x7",SUMIFS(Transaksi!$E:$E,Transaksi!$B:$B,"Xseven",Transaksi!$D:$D,""),0)) -> 44 | L5: =Table3[[#This Row],[Column11]]+Table3[[#This Row],[Column19]] -> 26
A6: Dewasa S | B6: b01 | C6: =belanja!H7 -> 205000 | D6: =C6/12 -> 17083.333 | E6: =belanja!E7*12 -> 0 | F6: 32 | G6: =Table3[[#This Row],[Column10]]-Table3[[#This Row],[Column19]] -> 0 | H6: =14+32 -> 46 | J6: =Table3[[#This Row],[Column6]]+Table3[[#This Row],[Column5]]-Table3[[#This Row],[Column13]] -> 32 | K6: =IF($B6="","",SUMIF(Transaksi!$D:$D,$B6,Transaksi!$E:$E)+IF($B6="das",SUMIFS(Transaksi!$E:$E,Transaksi!$B:$B,"Daster",Transaksi!$D:$D,""),0)+IF($B6="x7",SUMIFS(Transaksi!$E:$E,Transaksi!$B:$B,"Xseven",Transaksi!$D:$D,""),0)) -> 14 | L6: =Table3[[#This Row],[Column11]]+Table3[[#This Row],[Column19]] -> 32
A7: Dewasa M | B7: b02 | C7: =belanja!H8 -> 220000 | D7: =C7/12 -> 18333.333 | E7: =belanja!E8*12 -> 12 | F7: 41 | G7: =Table3[[#This Row],[Column10]]-Table3[[#This Row],[Column19]] -> 13 | H7: =20+29 -> 49 | J7: =Table3[[#This Row],[Column6]]+Table3[[#This Row],[Column5]]-Table3[[#This Row],[Column13]] -> 28 | K7: =IF($B7="","",SUMIF(Transaksi!$D:$D,$B7,Transaksi!$E:$E)+IF($B7="das",SUMIFS(Transaksi!$E:$E,Transaksi!$B:$B,"Daster",Transaksi!$D:$D,""),0)+IF($B7="x7",SUMIFS(Transaksi!$E:$E,Transaksi!$B:$B,"Xseven",Transaksi!$D:$D,""),0)) -> 21 | L7: =Table3[[#This Row],[Column11]]+Table3[[#This Row],[Column19]] -> 41
A8: Dewasa L | B8: b03 | C8: =belanja!H9 -> 235000 | D8: =C8/12 -> 19583.333 | E8: =belanja!E9*12 -> 12 | F8: 43 | G8: =Table3[[#This Row],[Column10]]-Table3[[#This Row],[Column19]] -> 12 | H8: =31+16 -> 47 | J8: =Table3[[#This Row],[Column6]]+Table3[[#This Row],[Column5]]-Table3[[#This Row],[Column13]] -> 31 | K8: =IF($B8="","",SUMIF(Transaksi!$D:$D,$B8,Transaksi!$E:$E)+IF($B8="das",SUMIFS(Transaksi!$E:$E,Transaksi!$B:$B,"Daster",Transaksi!$D:$D,""),0)+IF($B8="x7",SUMIFS(Transaksi!$E:$E,Transaksi!$B:$B,"Xseven",Transaksi!$D:$D,""),0)) -> 16 | L8: =Table3[[#This Row],[Column11]]+Table3[[#This Row],[Column19]] -> 43
A9: Dewasa XL | B9: b04 | C9: =belanja!H10 -> 250000 | D9: =C9/12 -> 20833.333 | E9: =belanja!E10*12 -> 0 | F9: 41 | G9: =Table3[[#This Row],[Column10]]-Table3[[#This Row],[Column19]] -> 12 | H9: =29+8 -> 37 | J9: =Table3[[#This Row],[Column6]]+Table3[[#This Row],[Column5]]-Table3[[#This Row],[Column13]] -> 29 | K9: =IF($B9="","",SUMIF(Transaksi!$D:$D,$B9,Transaksi!$E:$E)+IF($B9="das",SUMIFS(Transaksi!$E:$E,Transaksi!$B:$B,"Daster",Transaksi!$D:$D,""),0)+IF($B9="x7",SUMIFS(Transaksi!$E:$E,Transaksi!$B:$B,"Xseven",Transaksi!$D:$D,""),0)) -> 8 | L9: =Table3[[#This Row],[Column11]]+Table3[[#This Row],[Column19]] -> 41
A10: Dewasa XXL | B10: b05 | C10: =belanja!H11 -> 290000 | D10: =C10/12 -> 24166.667 | E10: =belanja!E11*12 -> 0 | F10: 38 | G10: =Table3[[#This Row],[Column10]]-Table3[[#This Row],[Column19]] -> 8 | H10: =30+3 -> 33 | J10: =Table3[[#This Row],[Column6]]+Table3[[#This Row],[Column5]]-Table3[[#This Row],[Column13]] -> 30 | K10: =IF($B10="","",SUMIF(Transaksi!$D:$D,$B10,Transaksi!$E:$E)+IF($B10="das",SUMIFS(Transaksi!$E:$E,Transaksi!$B:$B,"Daster",Transaksi!$D:$D,""),0)+IF($B10="x7",SUMIFS(Transaksi!$E:$E,Transaksi!$B:$B,"Xseven",Transaksi!$D:$D,""),0)) -> 3 | L10: =Table3[[#This Row],[Column11]]+Table3[[#This Row],[Column19]] -> 38
A11: Spandex M | B11: c01 | C11: =belanja!H12 -> 375000 | D11: =C11/12 -> 31250 | E11: =belanja!E12*12 -> 6 | F11: =8+8 -> 16 | G11: =Table3[[#This Row],[Column10]]-Table3[[#This Row],[Column19]] -> 8 | H11: =7+8 -> 15 | J11: =Table3[[#This Row],[Column6]]+Table3[[#This Row],[Column5]]-Table3[[#This Row],[Column13]] -> 8 | K11: =IF($B11="","",SUMIF(Transaksi!$D:$D,$B11,Transaksi!$E:$E)+IF($B11="das",SUMIFS(Transaksi!$E:$E,Transaksi!$B:$B,"Daster",Transaksi!$D:$D,""),0)+IF($B11="x7",SUMIFS(Transaksi!$E:$E,Transaksi!$B:$B,"Xseven",Transaksi!$D:$D,""),0)) -> 7 | L11: =Table3[[#This Row],[Column11]]+Table3[[#This Row],[Column19]] -> 16
A12: Spandex L | B12: c02 | C12: =belanja!H13 -> 395000 | D12: =C12/12 -> 32916.667 | E12: =belanja!E13*12 -> 12 | F12: 14 | G12: =Table3[[#This Row],[Column10]]-Table3[[#This Row],[Column19]] -> 6 | H12: =8+11 -> 19 | J12: =Table3[[#This Row],[Column6]]+Table3[[#This Row],[Column5]]-Table3[[#This Row],[Column13]] -> 8 | K12: =IF($B12="","",SUMIF(Transaksi!$D:$D,$B12,Transaksi!$E:$E)+IF($B12="das",SUMIFS(Transaksi!$E:$E,Transaksi!$B:$B,"Daster",Transaksi!$D:$D,""),0)+IF($B12="x7",SUMIFS(Transaksi!$E:$E,Transaksi!$B:$B,"Xseven",Transaksi!$D:$D,""),0)) -> 11 | L12: =Table3[[#This Row],[Column11]]+Table3[[#This Row],[Column19]] -> 14
A13: Spandex XL | B13: c03 | C13: =belanja!H14 -> 425000 | D13: =C13/12 -> 35416.667 | E13: =belanja!E14*12 -> 6 | F13: 13 | G13: =Table3[[#This Row],[Column10]]-Table3[[#This Row],[Column19]] -> 9 | H13: =7+13 -> 20 | J13: =Table3[[#This Row],[Column6]]+Table3[[#This Row],[Column5]]-Table3[[#This Row],[Column13]] -> 4 | K13: =IF($B13="","",SUMIF(Transaksi!$D:$D,$B13,Transaksi!$E:$E)+IF($B13="das",SUMIFS(Transaksi!$E:$E,Transaksi!$B:$B,"Daster",Transaksi!$D:$D,""),0)+IF($B13="x7",SUMIFS(Transaksi!$E:$E,Transaksi!$B:$B,"Xseven",Transaksi!$D:$D,""),0)) -> 16 | L13: =Table3[[#This Row],[Column11]]+Table3[[#This Row],[Column19]] -> 13
A14: Spandex XXL | B14: c04 | C14: =belanja!H15 -> 480000 | D14: =C14/12 -> 40000 | E14: =belanja!E15*12 -> 6 | F14: 14 | G14: =Table3[[#This Row],[Column10]]-Table3[[#This Row],[Column19]] -> 6 | H14: =8+6 -> 14 | J14: =Table3[[#This Row],[Column6]]+Table3[[#This Row],[Column5]]-Table3[[#This Row],[Column13]] -> 8 | K14: =IF($B14="","",SUMIF(Transaksi!$D:$D,$B14,Transaksi!$E:$E)+IF($B14="das",SUMIFS(Transaksi!$E:$E,Transaksi!$B:$B,"Daster",Transaksi!$D:$D,""),0)+IF($B14="x7",SUMIFS(Transaksi!$E:$E,Transaksi!$B:$B,"Xseven",Transaksi!$D:$D,""),0)) -> 6 | L14: =Table3[[#This Row],[Column11]]+Table3[[#This Row],[Column19]] -> 14
A15: XSeven | B15: x7 | C15: 420000 | D15: =C15/12 -> 35000 | E15: =belanja!E16*12 -> 0 | F15: 14 | G15: =Table3[[#This Row],[Column10]]-Table3[[#This Row],[Column19]] -> 4 | H15: =14+14 -> 28 | J15: =Table3[[#This Row],[Column6]]+Table3[[#This Row],[Column5]]-Table3[[#This Row],[Column13]] -> 10 | K15: =IF($B15="","",SUMIF(Transaksi!$D:$D,$B15,Transaksi!$E:$E)+IF($B15="das",SUMIFS(Transaksi!$E:$E,Transaksi!$B:$B,"Daster",Transaksi!$D:$D,""),0)+IF($B15="x7",SUMIFS(Transaksi!$E:$E,Transaksi!$B:$B,"Xseven",Transaksi!$D:$D,""),0)) -> 18 | L15: =Table3[[#This Row],[Column11]]+Table3[[#This Row],[Column19]] -> 14
A16: Daster | B16: das | C16: 650000 | D16: =C16/20 -> 32500 | E16: =belanja!D17*12 -> 0 | F16: 3 | G16: =Table3[[#This Row],[Column10]]-Table3[[#This Row],[Column19]] -> 0 | H16: =3+6 -> 9 | J16: =Table3[[#This Row],[Column6]]+Table3[[#This Row],[Column5]]-Table3[[#This Row],[Column13]] -> 3 | K16: =IF($B16="","",SUMIF(Transaksi!$D:$D,$B16,Transaksi!$E:$E)+IF($B16="das",SUMIFS(Transaksi!$E:$E,Transaksi!$B:$B,"Daster",Transaksi!$D:$D,""),0)+IF($B16="x7",SUMIFS(Transaksi!$E:$E,Transaksi!$B:$B,"Xseven",Transaksi!$D:$D,""),0)) -> 6 | L16: =Table3[[#This Row],[Column11]]+Table3[[#This Row],[Column19]] -> 3

Sheet Dashboard

Sheet belanja
A1: BELANJA KE UDA 4/5/26
A2: Nama_Barang | B2: kode | C2: Harga_pokok_lusin | D2: pokok_belanja | E2: belanja_lusin | F2: jml_pcs_belanja | G2: jumlah_belanja+stok | H2: Harga+komisi_uda | I2: sum_belanja | J2: total_belanja
A3: Setelan S | B3: a01 | C3: 245000 | D3: =E3*C3 -> 490000 | E3: 2 | F3: =E3*12 -> 24 | G3: =F3+Stok_Baju!L2 -> 58 | H3: =C3+15000 -> 260000 | I3: =H3*E3 -> 520000 | J3: =SUM(I3:I16) -> 3740000
A4: Setelan M | B4: a02 | C4: 260000 | D4: =E4*C4 -> 520000 | E4: 2 | F4: =E4*12 -> 24 | G4: =F4+Stok_Baju!L3 -> 61 | H4: =C4+15000 -> 275000 | I4: =H4*E4 -> 550000
A5: Setelan L | B5: a03 | C5: 270000 | D5: =E5*C5 -> 540000 | E5: 2 | F5: =E5*12 -> 24 | G5: =F5+Stok_Baju!L4 -> 64 | H5: =C5+15000 -> 285000 | I5: =H5*E5 -> 570000
A6: Setelan XL | B6: a04 | C6: 290000 | D6: =E6*C6 -> 580000 | E6: 2 | F6: =E6*12 -> 24 | G6: =F6+Stok_Baju!L5 -> 50 | H6: =C6+15000 -> 305000 | I6: =H6*E6 -> 610000
A7: Dewasa S | B7: b01 | C7: 190000 | D7: =E7*C7 -> 0 | E7: 0 | F7: =E7*12 -> 0 | G7: =F7+Stok_Baju!L6 -> 32 | H7: =C7+15000 -> 205000 | I7: =H7*E7 -> 0
A8: Dewasa M | B8: b02 | C8: 205000 | D8: =E8*C8 -> 205000 | E8: 1 | F8: =E8*12 -> 12 | G8: =F8+Stok_Baju!L7 -> 53 | H8: =C8+15000 -> 220000 | I8: =H8*E8 -> 220000
A9: Dewasa L | B9: b03 | C9: 220000 | D9: =E9*C9 -> 220000 | E9: 1 | F9: =E9*12 -> 12 | G9: =F9+Stok_Baju!L8 -> 55 | H9: =C9+15000 -> 235000 | I9: =H9*E9 -> 235000
A10: Dewasa XL | B10: b04 | C10: 235000 | D10: =E10*C10 -> 0 | E10: 0 | F10: =E10*12 -> 0 | G10: =F10+Stok_Baju!L9 -> 41 | H10: =C10+15000 -> 250000 | I10: =H10*E10 -> 0
A11: Dewasa XXL | B11: b05 | C11: 275000 | D11: =E11*C11 -> 0 | E11: 0 | F11: =E11*12 -> 0 | G11: =F11+Stok_Baju!L10 -> 38 | H11: =C11+15000 -> 290000 | I11: =H11*E11 -> 0
A12: Spandex M | B12: c01 | C12: 360000 | D12: =E12*C12 -> 180000 | E12: 0.5 | F12: =E12*12 -> 6 | G12: =F12+Stok_Baju!L11 -> 22 | H12: =C12+15000 -> 375000 | I12: =H12*E12 -> 187500
A13: Spandex L | B13: c02 | C13: 380000 | D13: =E13*C13 -> 380000 | E13: 1 | F13: =E13*12 -> 12 | G13: =F13+Stok_Baju!L12 -> 26 | H13: =C13+15000 -> 395000 | I13: =H13*E13 -> 395000
A14: Spandex XL | B14: c03 | C14: 410000 | D14: =E14*C14 -> 205000 | E14: 0.5 | F14: =E14*12 -> 6 | G14: =F14+Stok_Baju!L13 -> 19 | H14: =C14+15000 -> 425000 | I14: =H14*E14 -> 212500
A15: Spandex XXL | B15: c04 | C15: 465000 | D15: =E15*C15 -> 232500 | E15: 0.5 | F15: =E15*12 -> 6 | G15: =F15+Stok_Baju!L14 -> 20 | H15: =C15+15000 -> 480000 | I15: =H15*E15 -> 240000
A16: XSeven | B16: x7 | C16: 420000 | D16: =E16*C16 -> 0 | E16: 0 | F16: =E16*12 -> 0 | G16: =F16+Stok_Baju!L15 -> 14 | I16: =(C16*E16)+(15000*E16) -> 0
A17: Daster | B17: das | C17: 650000 | D17: =E17*C17 -> 0 | F17: =E17+Stok_Baju!#REF! -> #REF!
